Workbook

Sheet Consolidate rows
A1: Consolidate rows in Excel with formulas
A2: Date | B2: Department | C2: Amount | E2: Department | F2: Amount
A3: 45658 | B3: Sales | C3: 1250 | E3: Sales | F3: 10960
A4: 45658 | B4: Marketing | C4: 980 | E4: Marketing | F4: 5280
A5: 45660 | B5: Sales | C5: 1540 | E5: Support | F5: 2690
A6: 45661 | B6: Support | C6: 620 | E6: Finance | F6: 8410
A7: 45662 | B7: Sales | C7: 1310
A8: 45663 | B8: Finance | C8: 2200
A9: 45664 | B9: Marketing | C9: 1120
A10: 45665 | B10: Support | C10: 700
A11: 45667 | B11: Sales | C11: 1890
A12: 45667 | B12: Finance | C12: 1760
A13: 45669 | B13: Marketing | C13: 1050
A14: 45669 | B14: Sales | C14: 1420
A15: 45670 | B15: Support | C15: 660
A16: 45671 | B16: Finance | C16: 2340
A17: 45672 | B17: Sales | C17: 1670
A18: 45673 | B18: Marketing | C18: 930
... A22: 45677 | B22: Marketing | C22: 1200

Sheet Consolidate columns
A1: Consolidate columns in Excel with formulas
A2: Department | B2: Jan | C2: Feb | D2: Mar | E2: Total | F2: Average
A3: Administration | B3: 1200 | C3: 1400 | D3: 1650 | E3: =SUM(B3:D3) -> 4250 | F3: =AVERAGE(B3:D3) -> 1416.6667
A4: Customer Support | B4: 1450 | C4: 1320 | D4: 1750 | E4: =SUM(B4:D4) -> 4520 | F4: =AVERAGE(B4:D4) -> 1506.6667
A5: Finance | B5: 1600 | C5: 1600 | D5: 1180 | E5: =SUM(B5:D5) -> 4380 | F5: =AVERAGE(B5:D5) -> 1460
A6: Human Resources | B6: 1150 | C6: 1750 | D6: 1450 | E6: =SUM(B6:D6) -> 4350 | F6: =AVERAGE(B6:D6) -> 1450
A7: Information Technology | B7: 1250 | C7: 1800 | D7: 2000 | E7: =SUM(B7:D7) -> 5050 | F7: =AVERAGE(B7:D7) -> 1683.3333
A8: Legal | B8: 1850 | C8: 1500 | D8: 1120 | E8: =SUM(B8:D8) -> 4470 | F8: =AVERAGE(B8:D8) -> 1490
A9: Logistics | B9: 1350 | C9: 1010 | D9: 1250 | E9: =SUM(B9:D9) -> 3610 | F9: =AVERAGE(B9:D9) -> 1203.3333
A10: Marketing | B10: 1200 | C10: 1550 | D10: 1550 | E10: =SUM(B10:D10) -> 4300 | F10: =AVERAGE(B10:D10) -> 1433.3333
A11: Operations | B11: 1950 | C11: 1700 | D11: 1900 | E11: =SUM(B11:D11) -> 5550 | F11: =AVERAGE(B11:D11) -> 1850
A12: Procurement | B12: 1350 | C12: 1080 | D12: 1500 | E12: =SUM(B12:D12) -> 3930 | F12: =AVERAGE(B12:D12) -> 1310
A13: Product Management | B13: 1400 | C13: 1000 | D13: 1650 | E13: =SUM(B13:D13) -> 4050 | F13: =AVERAGE(B13:D13) -> 1350
A14: Quality Assurance | B14: 1100 | C14: 1450 | D14: 1600 | E14: =SUM(B14:D14) -> 4150 | F14: =AVERAGE(B14:D14) -> 1383.3333
... A17: Training and Development | B17: 1500 | C17: 1050 | D17: 1400 | E17: =SUM(B17:D17) -> 3950 | F17: =AVERAGE(B17:D17) -> 1316.6667

Sheet Report 1
G1: Item | H1: Jan | I1: Feb | J1: Mar
G2: Biscuits | H2: 434 | I2: 310 | J2: 170
G3: Brownies | H3: 170 | I3: 250 | J3: 220
G4: Cakes | H4: 110 | J4: 340
G5: Candy Bars | H5: 120 | I5: 180 | J5: 160
G6: Cheesecake | H6: 210 | I6: 300 | J6: 270
G7: Chocolate | H7: 180 | I7: 260 | J7: 210
G8: Cookies | H8: 130 | I8: 190 | J8: 150
G9: Croissants | H9: 175 | I9: 245 | J9: 215
G10: Cupcakes | H10: 150 | I10: 210 | J10: 190
G11: Donuts | H11: 160 | J11: 180
G12: Fudge | H12: 165 | I12: 235 | J12: 205
G13: Ice-cream | H13: 110 | I13: 220 | J13: 160
G14: Macarons | H14: 220 | I14: 310 | J14: 280
G15: Muffins | H15: 140 | I15: 200 | J15: 170
G16: Pancakes | H16: 155 | I16: 215 | J16: 185
G17: Pastries | H17: 190 | I17: 270 | J17: 240
G18: Pies | H18: 200 | I18: 290
G19: Sweets | H19: 250 | I19: 140 | J19: 200
G20: Tarts | H20: 185 | I20: 265 | J20: 235
G21: Waffles | H21: 145 | I21: 205 | J21: 175

Sheet Report 2
F3: Item | G3: Jan | H3: Feb | I3: Mar
F4: Waffles | G4: 160 | H4: 170 | I4: 200
F5: Tarts | G5: 220 | H5: 270 | I5: 190
F6: Sweets | G6: 245 | H6: 240 | I6: 235
F7: Pies | G7: 140 | H7: 145 | I7: 140
F8: Pastries | G8: 130 | H8: 250 | I8: 190
F9: Pancakes | G9: 210 | H9: 110 | I9: 150
F10: Muffins | G10: 310 | H10: 150 | I10: 190
F11: Macarons | G11: 180 | H11: 290 | I11: 205
F12: Ice-cream | G12: 100 | H12: 210 | I12: 220
F13: Fudge | G13: 215 | H13: 200 | I13: 185
F14: Donuts | G14: 140 | H14: 215 | I14: 200
F15: Cupcakes | G15: 180 | H15: 210 | I15: 120
... F19: Cheesecake | G19: 180 | H19: 250 | I19: 165
F20: Candy Bars | G20: 280 | H20: 175
F21: Cakes | G21: 310 | I21: 220
F22: Brownies | G22: 235 | H22: 205 | I22: 175
F23: Biscuits | G23: 170 | H23: 185 | I23: 300

Sheet Report 3
A1: Item | B1: Jan | C1: Feb | D1: Mar
A2: Sweets | B2: 190 | C2: 400 | D2: 250
A3: Biscuits | B3: 155 | C3: 160 | D3: 260
A4: Ice-cream | B4: 320 | C4: 175 | D4: 235
A5: Cakes | B5: 270 | C5: 460 | D5: 190
A6: Chocolate | B6: 190 | C6: 160 | D6: 250
A7: Cookies | B7: 145 | C7: 220 | D7: 300
A8: Donuts | B8: 310 | C8: 140 | D8: 160
A9: Muffins | B9: 150 | C9: 250 | D9: 210
A10: Brownies | B10: 140 | C10: 270 | D10: 205
A11: Cupcakes | B11: 290 | C11: 245 | D11: 180
A12: Pastries | C12: 100 | D12: 220
A13: Candy Bars | B13: 190 | C13: 200 | D13: 120
A14: Pies | B14: 165 | D14: 130
A15: Waffles | B15: 200 | C15: 210 | D15: 175
A16: Pancakes | B16: 180 | C16: 280 | D16: 265
A17: Croissants | B17: 210 | C17: 310 | D17: 215
A18: Macarons | B18: 215 | C18: 185 | D18: 140
A19: Fudge | B19: 200 | C19: 240 | D19: 170
A20: Cheesecake | B20: 340 | C20: 170 | D20: 150
A21: Tarts | B21: 110 | C21: 220 | D21: 180

Sheet staic report
B1: Jan | C1: Feb | D1: Mar
A2: Biscuits | B2: 725 | C2: 655 | D2: 730
A3: Brownies | B3: 545 | C3: 725 | D3: 600
A4: Cakes | B4: 690 | C4: 460 | D4: 750
A5: Candy Bars | B5: 590 | C5: 555 | D5: 280
A6: Cheesecake | B6: 730 | C6: 720 | D6: 585
A7: Chocolate | B7: 710 | C7: 575 | D7: 630
A8: Cookies | B8: 540 | C8: 680 | D8: 710
A9: Croissants | B9: 545 | C9: 665 | D9: 590
A10: Cupcakes | B10: 620 | C10: 665 | D10: 490
A11: Donuts | B11: 610 | C11: 355 | D11: 540
A12: Fudge | B12: 580 | C12: 675 | D12: 560
A13: Ice-cream | B13: 530 | C13: 605 | D13: 615
... A21: Waffles | B21: 505 | C21: 585 | D21: 550

Sheet Dynamic
D4: Jan | E4: Feb | F4: Mar
C5: Excel-Consolidate-Data | D5: ='Report 1'!$H$2 -> 434 | E5: ='Report 1'!$I$2 -> 310 | F5: ='Report 1'!$J$2 -> 170
C6: Excel-Consolidate-Data | D6: ='Report 2'!$G$23 -> 170 | E6: ='Report 2'!$H$23 -> 185 | F6: ='Report 2'!$I$23 -> 300
C7: Excel-Consolidate-Data | D7: ='Report 3'!$B$3 -> 155 | E7: ='Report 3'!$C$3 -> 160 | F7: ='Report 3'!$D$3 -> 260
B8: Biscuits | D8: =SUM(D5:D7) -> 759 | E8: =SUM(E5:E7) -> 655 | F8: =SUM(F5:F7) -> 730
C9: Excel-Consolidate-Data | D9: ='Report 1'!$H$3 -> 170 | E9: ='Report 1'!$I$3 -> 250 | F9: ='Report 1'!$J$3 -> 220
C10: Excel-Consolidate-Data | D10: ='Report 2'!$G$22 -> 235 | E10: ='Report 2'!$H$22 -> 205 | F10: ='Report 2'!$I$22 -> 175
C11: Excel-Consolidate-Data | D11: ='Report 3'!$B$10 -> 140 | E11: ='Report 3'!$C$10 -> 270 | F11: ='Report 3'!$D$10 -> 205
B12: Brownies | D12: =SUM(D9:D11) -> 545 | E12: =SUM(E9:E11) -> 725 | F12: =SUM(F9:F11) -> 600
C13: Excel-Consolidate-Data | D13: ='Report 1'!$H$4 -> 110 | F13: ='Report 1'!$J$4 -> 340
C14: Excel-Consolidate-Data | D14: ='Report 2'!$G$21 -> 310 | F14: ='Report 2'!$I$21 -> 220
C15: Excel-Consolidate-Data | D15: ='Report 3'!$B$5 -> 270 | E15: ='Report 3'!$C$5 -> 460 | F15: ='Report 3'!$D$5 -> 190
B16: Cakes | D16: =SUM(D13:D15) -> 690 | E16: =SUM(E13:E15) -> 460 | F16: =SUM(F13:F15) -> 750
C17: Excel-Consolidate-Data | D17: ='Report 1'!$H$5 -> 120 | E17: ='Report 1'!$I$5 -> 180 | F17: ='Report 1'!$J$5 -> 160
C18: Excel-Consolidate-Data | D18: ='Report 2'!$G$20 -> 280 | E18: ='Report 2'!$H$20 -> 175
C19: Excel-Consolidate-Data | D19: ='Report 3'!$B$13 -> 190 | E19: ='Report 3'!$C$13 -> 200 | F19: ='Report 3'!$D$13 -> 120
B20: Candy Bars | D20: =SUM(D17:D19) -> 590 | E20: =SUM(E17:E19) -> 555 | F20: =SUM(F17:F19) -> 280
C21: Excel-Consolidate-Data | D21: ='Report 1'!$H$6 -> 210 | E21: ='Report 1'!$I$6 -> 300 | F21: ='Report 1'!$J$6 -> 270
C22: Excel-Consolidate-Data | D22: ='Report 2'!$G$19 -> 180 | E22: ='Report 2'!$H$19 -> 250 | F22: ='Report 2'!$I$19 -> 165
C23: Excel-Consolidate-Data | D23: ='Report 3'!$B$20 -> 340 | E23: ='Report 3'!$C$20 -> 170 | F23: ='Report 3'!$D$20 -> 150
B24: Cheesecake | D24: =SUM(D21:D23) -> 730 | E24: =SUM(E21:E23) -> 720 | F24: =SUM(F21:F23) -> 585
C25: Excel-Consolidate-Data | D25: ='Report 1'!$H$7 -> 180 | E25: ='Report 1'!$I$7 -> 260 | F25: ='Report 1'!$J$7 -> 210
C26: Excel-Consolidate-Data | D26: ='Report 2'!$G$18 -> 340 | E26: ='Report 2'!$H$18 -> 155 | F26: ='Report 2'!$I$18 -> 170
C27: Excel-Consolidate-Data | D27: ='Report 3'!$B$6 -> 190 | E27: ='Report 3'!$C$6 -> 160 | F27: ='Report 3'!$D$6 -> 250
B28: Chocolate | D28: =SUM(D25:D27) -> 710 | E28: =SUM(E25:E27) -> 575 | F28: =SUM(F25:F27) -> 630
C29: Excel-Consolidate-Data | D29: ='Report 1'!$H$8 -> 130 | E29: ='Report 1'!$I$8 -> 190 | F29: ='Report 1'!$J$8 -> 150
C30: Excel-Consolidate-Data | D30: ='Report 2'!$G$17 -> 265 | E30: ='Report 2'!$H$17 -> 270 | F30: ='Report 2'!$I$17 -> 260
C31: Excel-Consolidate-Data | D31: ='Report 3'!$B$7 -> 145 | E31: ='Report 3'!$C$7 -> 220 | F31: ='Report 3'!$D$7 -> 300
B32: Cookies | D32: =SUM(D29:D31) -> 540 | E32: =SUM(E29:E31) -> 680 | F32: =SUM(F29:F31) -> 710
C33: Excel-Consolidate-Data | D33: ='Report 1'!$H$9 -> 175 | E33: ='Report 1'!$I$9 -> 245 | F33: ='Report 1'!$J$9 -> 215
C34: Excel-Consolidate-Data | D34: ='Report 2'!$G$16 -> 160 | E34: ='Report 2'!$H$16 -> 110 | F34: ='Report 2'!$I$16 -> 160
C35: Excel-Consolidate-Data | D35: ='Report 3'!$B$17 -> 210 | E35: ='Report 3'!$C$17 -> 310 | F35: ='Report 3'!$D$17 -> 215
B36: Croissants | D36: =SUM(D33:D35) -> 545 | E36: =SUM(E33:E35) -> 665 | F36: =SUM(F33:F35) -> 590
C37: Excel-Consolidate-Data | D37: ='Report 1'!$H$10 -> 150 | E37: ='Report 1'!$I$10 -> 210 | F37: ='Report 1'!$J$10 -> 190
C38: Excel-Consolidate-Data | D38: ='Report 2'!$G$15 -> 180 | E38: ='Report 2'!$H$15 -> 210 | F38: ='Report 2'!$I$15 -> 120
C39: Excel-Consolidate-Data | D39: ='Report 3'!$B$11 -> 290 | E39: ='Report 3'!$C$11 -> 245 | F39: ='Report 3'!$D$11 -> 180
B40: Cupcakes | D40: =SUM(D37:D39) -> 620 | E40: =SUM(E37:E39) -> 665 | F40: =SUM(F37:F39) -> 490
C41: Excel-Consolidate-Data | D41: ='Report 1'!$H$11 -> 160 | F41: ='Report 1'!$J$11 -> 180
C42: Excel-Consolidate-Data | D42: ='Report 2'!$G$14 -> 140 | E42: ='Report 2'!$H$14 -> 215 | F42: ='Report 2'!$I$14 -> 200
C43: Excel-Consolidate-Data | D43: ='Report 3'!$B$8 -> 310 | E43: ='Report 3'!$C$8 -> 140 | F43: ='Report 3'!$D$8 -> 160
...
